<mujoco model="ry_convert">
  <asset />
  <actuator>
    <position name="l_joint1" joint="l_joint1" forcerange="-150 150" />
    <position name="l_joint2" joint="l_joint2" forcerange="-150 150" />
    <position name="l_fing" joint="l_fing" forcerange="-150 150" />
    <position name="r_joint1" joint="r_joint1" forcerange="-150 150" />
    <position name="r_joint2" joint="r_joint2" forcerange="-150 150" />
    <position name="r_fing" joint="r_fing" forcerange="-150 150" />
  </actuator>
  <worldbody>
    <body name="l_base" pos="0.0 0.0 0.5">
      <body name="l_joint1">
        <inertial pos="0 0 0" mass="0.01" diaginertia="1e-5 1e-5 1e-5" />
        <joint name="l_joint1" type="slide" axis="1 0 0" />
        <body name="l_joint2">
          <inertial pos="0 0 0" mass="0.01" diaginertia="1e-5 1e-5 1e-5" />
          <joint name="l_joint2" type="slide" axis="0 1 0" />
          <body name="l_fing">
            <geom type="sphere" size="0.05" />
            <joint name="l_fing" type="slide" axis="0 0 1" />
          </body>
        </body>
      </body>
    </body>
    <body name="r_base" pos="0.0 0.0 0.5">
      <body name="r_joint1" pos="0.2 0.0 0.0">
        <inertial pos="0 0 0" mass="0.01" diaginertia="1e-5 1e-5 1e-5" />
        <joint name="r_joint1" type="slide" axis="1 0 0" />
        <body name="r_joint2">
          <inertial pos="0 0 0" mass="0.01" diaginertia="1e-5 1e-5 1e-5" />
          <joint name="r_joint2" type="slide" axis="0 1 0" />
          <body name="r_fing">
            <geom type="sphere" size="0.05" />
            <joint name="r_fing" type="slide" axis="0 0 1" />
          </body>
        </body>
      </body>
    </body>
    <body name="base">
      <body name="table" pos="0.0 0.0 0.1">
        <geom type="box" size="0.5 0.5 0.05" />
        <body name="wall" pos="0.45 0.0 0.3">
          <geom type="box" size="0.05 0.5 0.25" />
        </body>
        <body name="box" pos="-0.05 -0.35 0.25">
          <geom type="box" size="0.45 0.15 0.2" />
        </body>
      </body>
    </body>
    <body name="obj" pos="0.0 0.0 0.3">
      <geom type="sphere" size="0.1" />
      <freejoint />
    </body>
  </worldbody>
</mujoco>
